<?xml version='1.0' encoding='utf-8'?>
<robot name="biped">
  
  <link name="assy_formfg___kd_b_102b_torso_btm">
    <inertial>
      <origin xyz="-1.03459e-05 -0.0247199 -0.0491206" rpy="0 0 0" />
      <mass value="4.31925" />
      <inertia ixx="0.011234" ixy="2.07006e-05" ixz="-1.55136e-06" iyy="0.0113947" iyz="6.2346e-06" izz="0.0105519" />
    </inertial>
    
    <visual>
      <origin xyz="0.161 -0.0416054 0.388488" rpy="-1.5708 0 -0" />
      <geometry>
        <mesh filename="assets/rs04.stl" />
      </geometry>
      <material name="rs04_material">
        <color rgba="0.929412 0.505882 0 1" />
      </material>
    </visual>
    <collision>
      <origin xyz="0.161 -0.0416054 0.388488" rpy="-1.5708 0 -0" />
      <geometry>
        <mesh filename="assets/rs04.stl" />
      </geometry>
    </collision>
    
    <visual>
      <origin xyz="0 -0.0246054 0.00448841" rpy="-1.5708 0 -0" />
      <geometry>
        <mesh filename="assets/assy_formfg___kd_b_102b_torso_btm.stl" />
      </geometry>
      <material name="assy_formfg___kd_b_102b_torso_btm_material">
        <color rgba="0.956863 0.956863 0.964706 1" />
      </material>
    </visual>
    <collision>
      <origin xyz="0 -0.0246054 0.00448841" rpy="-1.5708 0 -0" />
      <geometry>
        <mesh filename="assets/assy_formfg___kd_b_102b_torso_btm.stl" />
      </geometry>
    </collision>
    
    <visual>
      <origin xyz="-0.161 -0.00760544 0.388488" rpy="-1.5708 -0 3.14159" />
      <geometry>
        <mesh filename="assets/rs04.stl" />
      </geometry>
      <material name="rs04_2_material">
        <color rgba="0.929412 0.505882 0 1" />
      </material>
    </visual>
    <collision>
      <origin xyz="-0.161 -0.00760544 0.388488" rpy="-1.5708 -0 3.14159" />
      <geometry>
        <mesh filename="assets/rs04.stl" />
      </geometry>
    </collision>
    
    <visual>
      <origin xyz="0 -0.0246054 0.00448841" rpy="-1.5708 0 -0" />
      <geometry>
        <mesh filename="assets/kd_d_101l_6061.stl" />
      </geometry>
      <material name="kd_d_101l_6061_material">
        <color rgba="0.956863 0.956863 0.964706 1" />
      </material>
    </visual>
    <collision>
      <origin xyz="0 -0.0246054 0.00448841" rpy="-1.5708 0 -0" />
      <geometry>
        <mesh filename="assets/kd_d_101l_6061.stl" />
      </geometry>
    </collision>
    
    <visual>
      <origin xyz="0 -0.0246054 0.00448841" rpy="-1.5708 0 -0" />
      <geometry>
        <mesh filename="assets/kd_d_101r_6061.stl" />
      </geometry>
      <material name="kd_d_101r_6061_material">
        <color rgba="0.956863 0.956863 0.964706 1" />
      </material>
    </visual>
    <collision>
      <origin xyz="0 -0.0246054 0.00448841" rpy="-1.5708 0 -0" />
      <geometry>
        <mesh filename="assets/kd_d_101r_6061.stl" />
      </geometry>
    </collision>
    
    <visual>
      <origin xyz="0 -0.0246054 0.00448841" rpy="-1.5708 0 -0" />
      <geometry>
        <mesh filename="assets/assy_formfg___kc_d_107r_r_cover.stl" />
      </geometry>
      <material name="assy_formfg___kc_d_107r_r_cover_material">
        <color rgba="0.956863 0.956863 0.964706 1" />
      </material>
    </visual>
    <collision>
      <origin xyz="0 -0.0246054 0.00448841" rpy="-1.5708 0 -0" />
      <geometry>
        <mesh filename="assets/assy_formfg___kc_d_107r_r_cover.stl" />
      </geometry>
    </collision>
    
    <visual>
      <origin xyz="-0 -0.0886054 -0.0595116" rpy="-0 0 -0" />
      <geometry>
        <mesh filename="assets/kd_d_104r_sus304.stl" />
      </geometry>
      <material name="kd_d_104r_sus304_material">
        <color rgba="0.956863 0.956863 0.964706 1" />
      </material>
    </visual>
    <collision>
      <origin xyz="-0 -0.0886054 -0.0595116" rpy="-0 0 -0" />
      <geometry>
        <mesh filename="assets/kd_d_104r_sus304.stl" />
      </geometry>
    </collision>
    
    <visual>
      <origin xyz="0 -0.0886054 -0.0595116" rpy="-0 -0 3.14159" />
      <geometry>
        <mesh filename="assets/kd_d_104l_sus304.stl" />
      </geometry>
      <material name="kd_d_104l_sus304_material">
        <color rgba="0.956863 0.956863 0.964706 1" />
      </material>
    </visual>
    <collision>
      <origin xyz="0 -0.0886054 -0.0595116" rpy="-0 -0 3.14159" />
      <geometry>
        <mesh filename="assets/kd_d_104l_sus304.stl" />
      </geometry>
    </collision>
    
    <visual>
      <origin xyz="0 -0.0246054 0.00448841" rpy="-1.5708 0 -0" />
      <geometry>
        <mesh filename="assets/assy_formfg___kc_d_107l_l_cover.stl" />
      </geometry>
      <material name="assy_formfg___kc_d_107l_l_cover_material">
        <color rgba="0.717647 0.717647 0.717647 1" />
      </material>
    </visual>
    <collision>
      <origin xyz="0 -0.0246054 0.00448841" rpy="-1.5708 0 -0" />
      <geometry>
        <mesh filename="assets/assy_formfg___kc_d_107l_l_cover.stl" />
      </geometry>
    </collision>
  </link>
  
  <link name="kd_d_102r_6061">
    <inertial>
      <origin xyz="-0.00547037 -0.00477853 -0.0395434" rpy="0 0 0" />
      <mass value="0.523694" />
      <inertia ixx="0.000883986" ixy="-8.13997e-05" ixz="-7.78777e-05" iyy="0.00116871" iyz="-0.000164372" izz="0.00125922" />
    </inertial>
    
    <visual>
      <origin xyz="-0 0.064 0.054" rpy="-3.14159 -1.5708 0" />
      <geometry>
        <mesh filename="assets/kd_d_105_sus304.stl" />
      </geometry>
      <material name="kd_d_105_sus304_material">
        <color rgba="0.956863 0.956863 0.964706 1" />
      </material>
    </visual>
    <collision>
      <origin xyz="-0 0.064 0.054" rpy="-3.14159 -1.5708 0" />
      <geometry>
        <mesh filename="assets/kd_d_105_sus304.stl" />
      </geometry>
    </collision>
    
    <visual>
      <origin xyz="-0 0.064 0.055" rpy="-3.14159 -1.5708 0" />
      <geometry>
        <mesh filename="assets/kd_d_103r_6061.stl" />
      </geometry>
      <material name="kd_d_103r_6061_material">
        <color rgba="0.956863 0.956863 0.964706 1" />
      </material>
    </visual>
    <collision>
      <origin xyz="-0 0.064 0.055" rpy="-3.14159 -1.5708 0" />
      <geometry>
        <mesh filename="assets/kd_d_103r_6061.stl" />
      </geometry>
    </collision>
    
    <visual>
      <origin xyz="0 0.064 0.055" rpy="-1.5708 -1.5708 0" />
      <geometry>
        <mesh filename="assets/kd_d_102r_6061.stl" />
      </geometry>
      <material name="kd_d_102r_6061_material">
        <color rgba="0.956863 0.956863 0.964706 1" />
      </material>
    </visual>
    <collision>
      <origin xyz="0 0.064 0.055" rpy="-1.5708 -1.5708 0" />
      <geometry>
        <mesh filename="assets/kd_d_102r_6061.stl" />
      </geometry>
    </collision>
  </link>
  
  <link name="kd_d_201r_6061">
    <inertial>
      <origin xyz="-0.000145033 -0.0585966 -0.0266073" rpy="0 0 0" />
      <mass value="2.43396" />
      <inertia ixx="0.0105345" ixy="-4.06249e-07" ixz="4.61482e-07" iyy="0.00328764" iyz="0.000384579" izz="0.0109014" />
    </inertial>
    
    <visual>
      <origin xyz="0.126 0.094 -0.02925" rpy="-3.14159 -0 0" />
      <geometry>
        <mesh filename="assets/kd_d_201r_6061.stl" />
      </geometry>
      <material name="kd_d_201r_6061_material">
        <color rgba="0.956863 0.956863 0.964706 1" />
      </material>
    </visual>
    <collision>
      <origin xyz="0.126 0.094 -0.02925" rpy="-3.14159 -0 0" />
      <geometry>
        <mesh filename="assets/kd_d_201r_6061.stl" />
      </geometry>
    </collision>
    
    <visual>
      <origin xyz="0.126 0.094 -0.02125" rpy="-0 -0 3.14159" />
      <geometry>
        <mesh filename="assets/kd_d_203_sus304.stl" />
      </geometry>
      <material name="kd_d_203_sus304_material">
        <color rgba="0.956863 0.956863 0.964706 1" />
      </material>
    </visual>
    <collision>
      <origin xyz="0.126 0.094 -0.02125" rpy="-0 -0 3.14159" />
      <geometry>
        <mesh filename="assets/kd_d_203_sus304.stl" />
      </geometry>
    </collision>
    
    <visual>
      <origin xyz="0.126 -0.11275 0.06875" rpy="-1.5708 -0 0" />
      <geometry>
        <mesh filename="assets/rs03.stl" />
      </geometry>
      <material name="rs03_material">
        <color rgba="0.929412 0.505882 0 1" />
      </material>
    </visual>
    <collision>
      <origin xyz="0.126 -0.11275 0.06875" rpy="-1.5708 -0 0" />
      <geometry>
        <mesh filename="assets/rs03.stl" />
      </geometry>
    </collision>
    
    <visual>
      <origin xyz="0.126 0.094 -0.02925" rpy="-3.14159 -0 0" />
      <geometry>
        <mesh filename="assets/rs03.stl" />
      </geometry>
      <material name="rs03_2_material">
        <color rgba="0.929412 0.505882 0 1" />
      </material>
    </visual>
    <collision>
      <origin xyz="0.126 0.094 -0.02925" rpy="-3.14159 -0 0" />
      <geometry>
        <mesh filename="assets/rs03.stl" />
      </geometry>
    </collision>
    
    <visual>
      <origin xyz="0.126 0.094 -0.02925" rpy="-3.14159 -0 0" />
      <geometry>
        <mesh filename="assets/kd_d_202r_6061.stl" />
      </geometry>
      <material name="kd_d_202r_6061_material">
        <color rgba="0.956863 0.956863 0.964706 1" />
      </material>
    </visual>
    <collision>
      <origin xyz="0.126 0.094 -0.02925" rpy="-3.14159 -0 0" />
      <geometry>
        <mesh filename="assets/kd_d_202r_6061.stl" />
      </geometry>
    </collision>
    
    <visual>
      <origin xyz="-0 0 -0.0716" rpy="-1.5708 -1.5708 0" />
      <geometry>
        <mesh filename="assets/ball_bearing_37x25x7.stl" />
      </geometry>
      <material name="ball_bearing_37x25x7_material">
        <color rgba="0.717647 0.709804 0.701961 1" />
      </material>
    </visual>
    <collision>
      <origin xyz="-0 0 -0.0716" rpy="-1.5708 -1.5708 0" />
      <geometry>
        <mesh filename="assets/ball_bearing_37x25x7.stl" />
      </geometry>
    </collision>
  </link>
  
  <link name="kd_d_301r_6061">
    <inertial>
      <origin xyz="-0.00178881 0.0135092 -0.173426" rpy="0 0 0" />
      <mass value="2.3872" />
      <inertia ixx="0.0154687" ixy="0.00019296" ixz="-0.00113935" iyy="0.0140272" iyz="0.00150683" izz="0.00405939" />
    </inertial>
    
    <visual>
      <origin xyz="0.126 0.004 0.236" rpy="-1.5708 -0 0" />
      <geometry>
        <mesh filename="assets/rs04.stl" />
      </geometry>
      <material name="rs04_3_material">
        <color rgba="0.929412 0.505882 0 1" />
      </material>
    </visual>
    <collision>
      <origin xyz="0.126 0.004 0.236" rpy="-1.5708 -0 0" />
      <geometry>
        <mesh filename="assets/rs04.stl" />
      </geometry>
    </collision>
    
    <visual>
      <origin xyz="0.126 0.004 0.236" rpy="-1.5708 -0 0" />
      <geometry>
        <mesh filename="assets/kd_d_302r_6061.stl" />
      </geometry>
      <material name="kd_d_302r_6061_material">
        <color rgba="0.956863 0.956863 0.964706 1" />
      </material>
    </visual>
    <collision>
      <origin xyz="0.126 0.004 0.236" rpy="-1.5708 -0 0" />
      <geometry>
        <mesh filename="assets/kd_d_302r_6061.stl" />
      </geometry>
    </collision>
    
    <visual>
      <origin xyz="0.126 0.004 0.236" rpy="-1.5708 -0 0" />
      <geometry>
        <mesh filename="assets/kd_d_301r_6061.stl" />
      </geometry>
      <material name="kd_d_301r_6061_material">
        <color rgba="0.956863 0.956863 0.964706 1" />
      </material>
    </visual>
    <collision>
      <origin xyz="0.126 0.004 0.236" rpy="-1.5708 -0 0" />
      <geometry>
        <mesh filename="assets/kd_d_301r_6061.stl" />
      </geometry>
    </collision>
    
    <visual>
      <origin xyz="-0.04445 0.021 -0.212" rpy="-0.628319 0 0" />
      <geometry>
        <mesh filename="assets/ball_bearing_37x25x7.stl" />
      </geometry>
      <material name="ball_bearing_37x25x7_2_material">
        <color rgba="0.717647 0.709804 0.701961 1" />
      </material>
    </visual>
    <collision>
      <origin xyz="-0.04445 0.021 -0.212" rpy="-0.628319 0 0" />
      <geometry>
        <mesh filename="assets/ball_bearing_37x25x7.stl" />
      </geometry>
    </collision>
    
    <visual>
      <origin xyz="0.126 -0.331447 0.0650811" rpy="-2.51327 -0 -3.14159" />
      <geometry>
        <mesh filename="assets/kd_d_403_6061.stl" />
      </geometry>
      <material name="kd_d_403_6061_material">
        <color rgba="0.956863 0.956863 0.964706 1" />
      </material>
    </visual>
    <collision>
      <origin xyz="0.126 -0.331447 0.0650811" rpy="-2.51327 -0 -3.14159" />
      <geometry>
        <mesh filename="assets/kd_d_403_6061.stl" />
      </geometry>
    </collision>
  </link>
  
  <link name="kd_d_401r_6061">
    <inertial>
      <origin xyz="0.123964 -0.0317009 -0.0201806" rpy="0 0 0" />
      <mass value="2.09836" />
      <inertia ixx="0.00342873" ixy="0.000744894" ixz="0.000680562" iyy="0.0173705" iyz="-3.04465e-05" izz="0.0172835" />
    </inertial>
    
    <visual>
      <origin xyz="-0.448 -0.017 0.104" rpy="-1.5708 -1.5708 0" />
      <geometry>
        <mesh filename="assets/kd_d_401r_6061.stl" />
      </geometry>
      <material name="kd_d_401r_6061_material">
        <color rgba="0.956863 0.956863 0.964706 1" />
      </material>
    </visual>
    <collision>
      <origin xyz="-0.448 -0.017 0.104" rpy="-1.5708 -1.5708 0" />
      <geometry>
        <mesh filename="assets/kd_d_401r_6061.stl" />
      </geometry>
    </collision>
    
    <visual>
      <origin xyz="0.105552 -0.062872 -0.022" rpy="-0 -1.5708 0" />
      <geometry>
        <mesh filename="assets/r_end_stop_ankle_6061.stl" />
      </geometry>
      <material name="r_end_stop_ankle_6061_material">
        <color rgba="0.956863 0.956863 0.964706 1" />
      </material>
    </visual>
    <collision>
      <origin xyz="0.105552 -0.062872 -0.022" rpy="-0 -1.5708 0" />
      <geometry>
        <mesh filename="assets/r_end_stop_ankle_6061.stl" />
      </geometry>
    </collision>
    
    <visual>
      <origin xyz="0.194052 -0.062872 -0.022" rpy="0 1.5708 0" />
      <geometry>
        <mesh filename="assets/r_end_stop_ankle_6061.stl" />
      </geometry>
      <material name="r_end_stop_ankle_6061_2_material">
        <color rgba="0.956863 0.956863 0.964706 1" />
      </material>
    </visual>
    <collision>
      <origin xyz="0.194052 -0.062872 -0.022" rpy="0 1.5708 0" />
      <geometry>
        <mesh filename="assets/r_end_stop_ankle_6061.stl" />
      </geometry>
    </collision>
    
    <visual>
      <origin xyz="-0.447447 -0.176632 -0.019" rpy="-0 0 -1.5708" />
      <geometry>
        <mesh filename="assets/kd_d_502_6061.stl" />
      </geometry>
      <material name="kd_d_502_6061_material">
        <color rgba="0.956863 0.956863 0.964706 1" />
      </material>
    </visual>
    <collision>
      <origin xyz="-0.447447 -0.176632 -0.019" rpy="-0 0 -1.5708" />
      <geometry>
        <mesh filename="assets/kd_d_502_6061.stl" />
      </geometry>
    </collision>
    
    <visual>
      <origin xyz="0.747053 -0.176632 -0.025" rpy="3.14159 0 -1.5708" />
      <geometry>
        <mesh filename="assets/kd_d_502_6061.stl" />
      </geometry>
      <material name="kd_d_502_6061_2_material">
        <color rgba="0.956863 0.956863 0.964706 1" />
      </material>
    </visual>
    <collision>
      <origin xyz="0.747053 -0.176632 -0.025" rpy="3.14159 0 -1.5708" />
      <geometry>
        <mesh filename="assets/kd_d_502_6061.stl" />
      </geometry>
    </collision>
    
    <visual>
      <origin xyz="0.191052 -0.176632 -0.575" rpy="1.5708 0 -1.5708" />
      <geometry>
        <mesh filename="assets/rs02.stl" />
      </geometry>
      <material name="rs02_material">
        <color rgba="0.929412 0.505882 0 1" />
      </material>
    </visual>
    <collision>
      <origin xyz="0.191052 -0.176632 -0.575" rpy="1.5708 0 -1.5708" />
      <geometry>
        <mesh filename="assets/rs02.stl" />
      </geometry>
    </collision>
    
    <visual>
      <origin xyz="-0.448 -0.017 0.104" rpy="-1.5708 -1.5708 0" />
      <geometry>
        <mesh filename="assets/kd_d_402r_6061.stl" />
      </geometry>
      <material name="kd_d_402r_6061_material">
        <color rgba="0.882353 0.882353 0.882353 1" />
      </material>
    </visual>
    <collision>
      <origin xyz="-0.448 -0.017 0.104" rpy="-1.5708 -1.5708 0" />
      <geometry>
        <mesh filename="assets/kd_d_402r_6061.stl" />
      </geometry>
    </collision>
    
    <visual>
      <origin xyz="0.102553 -0.176632 -0.575" rpy="1.5708 0 -1.5708" />
      <geometry>
        <mesh filename="assets/rs02.stl" />
      </geometry>
      <material name="rs02_2_material">
        <color rgba="0.929412 0.505882 0 1" />
      </material>
    </visual>
    <collision>
      <origin xyz="0.102553 -0.176632 -0.575" rpy="1.5708 0 -1.5708" />
      <geometry>
        <mesh filename="assets/rs02.stl" />
      </geometry>
    </collision>
  </link>
  
  <link name="arb_uj111_cross_bearing">
    <inertial>
      <origin xyz="8.901e-09 -1.5576e-08 -0.03" rpy="0 0 0" />
      <mass value="0.110039" />
      <inertia ixx="4.55522e-05" ixy="1.4e-11" ixz="1e-12" iyy="2.63882e-05" iyz="-4e-12" izz="2.63882e-05" />
    </inertial>
    
    <visual>
      <origin xyz="-0 -0 -0.03" rpy="-1.5708 -1.5708 0" />
      <geometry>
        <mesh filename="assets/arb_uj111_cross_bearing.stl" />
      </geometry>
      <material name="arb_uj111_cross_bearing_material">
        <color rgba="0.72549 0.733333 0.717647 1" />
      </material>
    </visual>
    <collision>
      <origin xyz="-0 -0 -0.03" rpy="-1.5708 -1.5708 0" />
      <geometry>
        <mesh filename="assets/arb_uj111_cross_bearing.stl" />
      </geometry>
    </collision>
  </link>
  
  <link name="foot_6061">
    <inertial>
      <origin xyz="-9.04e-10 0.0327815 -0.069626" rpy="0 0 0" />
      <mass value="0.427779" />
      <inertia ixx="0.0014449" ixy="-9e-12" ixz="-0" iyy="0.00161841" iyz="5.78063e-05" izz="0.00028165" />
    </inertial>
    
    <visual>
      <origin xyz="-0.0425 0.043 0.02" rpy="1.5708 1.5708 0" />
      <geometry>
        <mesh filename="assets/foot_6061.stl" />
      </geometry>
      <material name="foot_6061_material">
        <color rgba="0.956863 0.956863 0.964706 1" />
      </material>
    </visual>
    <collision>
      <origin xyz="-0.0425 0.043 0.02" rpy="1.5708 1.5708 0" />
      <geometry>
        <mesh filename="assets/foot_6061.stl" />
      </geometry>
    </collision>
  </link>
  
  <joint name="right_foot_roll_02" type="revolute">
    <origin xyz="-0 0.03 -0.03" rpy="-1.5708 -1.5708 0" />
    <parent link="arb_uj111_cross_bearing" />
    <child link="foot_6061" />
    <axis xyz="0 0 1" />
    <limit effort="15" velocity="10" lower="-0.261799" upper="0.261799" />
  </joint>
  
  <joint name="right_foot_pitch_02" type="revolute">
    <origin xyz="0.288552 -0.0326806 0.008" rpy="0 0 -0" />
    <parent link="kd_d_401r_6061" />
    <child link="arb_uj111_cross_bearing" />
    <axis xyz="0 0 1" />
    <limit effort="15" velocity="10" lower="-0.872665" upper="0.523599" />
  </joint>
  
  <joint name="right_knee_04" type="revolute">
    <origin xyz="0.022 0.021 -0.212" rpy="-0 1.5708 0" />
    <parent link="kd_d_301r_6061" />
    <child link="kd_d_401r_6061" />
    <axis xyz="0 0 1" />
    <limit effort="100" velocity="10" lower="0" upper="2.70526" />
  </joint>
  
  <joint name="right_hip_yaw_03" type="revolute">
    <origin xyz="0 -0.142 -0.02525" rpy="-1.5708 -0 -0" />
    <parent link="kd_d_201r_6061" />
    <child link="kd_d_301r_6061" />
    <axis xyz="0 0 1" />
    <limit effort="50" velocity="10" lower="-1.5708" upper="1.5708" />
  </joint>
  
  <joint name="right_hip_roll_03" type="revolute">
    <origin xyz="-0.02925 -0.03 -0.071" rpy="0 -1.5708 0" />
    <parent link="kd_d_102r_6061" />
    <child link="kd_d_201r_6061" />
    <axis xyz="0 0 1" />
    <limit effort="50" velocity="10" lower="-2.26893" upper="0.20944" />
  </joint>
  
  <joint name="right_hip_pitch_04" type="revolute">
    <origin xyz="-0.055 -0.0246054 -0.0595116" rpy="1.5708 0 1.5708" />
    <parent link="assy_formfg___kd_b_102b_torso_btm" />
    <child link="kd_d_102r_6061" />
    <axis xyz="0 0 1" />
    <limit effort="100" velocity="10" lower="-2.21657" upper="1.0472" />
  </joint>
  
  <link name="kd_d_102l_6061">
    <inertial>
      <origin xyz="0.00547051 -0.00478043 -0.0395434" rpy="0 0 0" />
      <mass value="0.523694" />
      <inertia ixx="0.000883977" ixy="8.14427e-05" ixz="7.7879e-05" iyy="0.00116871" iyz="-0.000164342" izz="0.0012592" />
    </inertial>
    
    <visual>
      <origin xyz="0 0.064 0.055" rpy="-1.5708 -1.5708 0" />
      <geometry>
        <mesh filename="assets/kd_d_102l_6061.stl" />
      </geometry>
      <material name="kd_d_102l_6061_material">
        <color rgba="0.956863 0.956863 0.964706 1" />
      </material>
    </visual>
    <collision>
      <origin xyz="0 0.064 0.055" rpy="-1.5708 -1.5708 0" />
      <geometry>
        <mesh filename="assets/kd_d_102l_6061.stl" />
      </geometry>
    </collision>
    
    <visual>
      <origin xyz="0 -0.0607264 0.054" rpy="0 -1.5708 0" />
      <geometry>
        <mesh filename="assets/kd_d_105_sus304.stl" />
      </geometry>
      <material name="kd_d_105_sus304_2_material">
        <color rgba="0.956863 0.956863 0.964706 1" />
      </material>
    </visual>
    <collision>
      <origin xyz="0 -0.0607264 0.054" rpy="0 -1.5708 0" />
      <geometry>
        <mesh filename="assets/kd_d_105_sus304.stl" />
      </geometry>
    </collision>
    
    <visual>
      <origin xyz="0 0.064 0.055" rpy="0 -1.5708 0" />
      <geometry>
        <mesh filename="assets/kd_d_103l_6061.stl" />
      </geometry>
      <material name="kd_d_103l_6061_material">
        <color rgba="0.956863 0.956863 0.964706 1" />
      </material>
    </visual>
    <collision>
      <origin xyz="0 0.064 0.055" rpy="0 -1.5708 0" />
      <geometry>
        <mesh filename="assets/kd_d_103l_6061.stl" />
      </geometry>
    </collision>
  </link>
  
  <link name="rs03">
    <inertial>
      <origin xyz="-0.000144775 0.0585805 -0.026592" rpy="0 0 0" />
      <mass value="2.43395" />
      <inertia ixx="0.0105388" ixy="4.98609e-06" ixz="-4.15171e-06" iyy="0.0032877" iyz="-0.000386693" izz="0.0109056" />
    </inertial>
    
    <visual>
      <origin xyz="-0 -0 -0.0646" rpy="1.5708 1.5708 0" />
      <geometry>
        <mesh filename="assets/ball_bearing_37x25x7.stl" />
      </geometry>
      <material name="ball_bearing_37x25x7_3_material">
        <color rgba="0.717647 0.709804 0.701961 1" />
      </material>
    </visual>
    <collision>
      <origin xyz="-0 -0 -0.0646" rpy="1.5708 1.5708 0" />
      <geometry>
        <mesh filename="assets/ball_bearing_37x25x7.stl" />
      </geometry>
    </collision>
    
    <visual>
      <origin xyz="0.126 0.094 -0.02925" rpy="-3.14159 -0 -0" />
      <geometry>
        <mesh filename="assets/rs03.stl" />
      </geometry>
      <material name="rs03_3_material">
        <color rgba="0.929412 0.505882 0 1" />
      </material>
    </visual>
    <collision>
      <origin xyz="0.126 0.094 -0.02925" rpy="-3.14159 -0 -0" />
      <geometry>
        <mesh filename="assets/rs03.stl" />
      </geometry>
    </collision>
    
    <visual>
      <origin xyz="0.126 -0.094 -0.02925" rpy="3.14159 0 -0" />
      <geometry>
        <mesh filename="assets/kd_d_201l_6061.stl" />
      </geometry>
      <material name="kd_d_201l_6061_material">
        <color rgba="0.956863 0.956863 0.964706 1" />
      </material>
    </visual>
    <collision>
      <origin xyz="0.126 -0.094 -0.02925" rpy="3.14159 0 -0" />
      <geometry>
        <mesh filename="assets/kd_d_201l_6061.stl" />
      </geometry>
    </collision>
    
    <visual>
      <origin xyz="0.126 -0.094 -0.02925" rpy="3.14159 0 -0" />
      <geometry>
        <mesh filename="assets/kd_d_202l_6061.stl" />
      </geometry>
      <material name="kd_d_202l_6061_material">
        <color rgba="0.956863 0.956863 0.964706 1" />
      </material>
    </visual>
    <collision>
      <origin xyz="0.126 -0.094 -0.02925" rpy="3.14159 0 -0" />
      <geometry>
        <mesh filename="assets/kd_d_202l_6061.stl" />
      </geometry>
    </collision>
    
    <visual>
      <origin xyz="0.126 -0.094 -0.02925" rpy="-3.14159 0 3.14159" />
      <geometry>
        <mesh filename="assets/kd_d_203_sus304.stl" />
      </geometry>
      <material name="kd_d_203_sus304_2_material">
        <color rgba="0.956863 0.956863 0.964706 1" />
      </material>
    </visual>
    <collision>
      <origin xyz="0.126 -0.094 -0.02925" rpy="-3.14159 0 3.14159" />
      <geometry>
        <mesh filename="assets/kd_d_203_sus304.stl" />
      </geometry>
    </collision>
    
    <visual>
      <origin xyz="0.126 0.11275 -0.11925" rpy="1.5708 0 -0" />
      <geometry>
        <mesh filename="assets/rs03.stl" />
      </geometry>
      <material name="rs03_4_material">
        <color rgba="0.929412 0.505882 0 1" />
      </material>
    </visual>
    <collision>
      <origin xyz="0.126 0.11275 -0.11925" rpy="1.5708 0 -0" />
      <geometry>
        <mesh filename="assets/rs03.stl" />
      </geometry>
    </collision>
  </link>
  
  <link name="kd_d_301l_6061">
    <inertial>
      <origin xyz="-0.0017883 -0.013508 -0.173323" rpy="0 0 0" />
      <mass value="2.38733" />
      <inertia ixx="0.0154522" ixy="-0.000193064" ixz="-0.00115262" iyy="0.0140108" iyz="-0.00153943" izz="0.00405975" />
    </inertial>
    
    <visual>
      <origin xyz="0.126 -0.004 0.236" rpy="1.5708 -0 0" />
      <geometry>
        <mesh filename="assets/kd_d_302l_6061.stl" />
      </geometry>
      <material name="kd_d_302l_6061_material">
        <color rgba="0.956863 0.956863 0.964706 1" />
      </material>
    </visual>
    <collision>
      <origin xyz="0.126 -0.004 0.236" rpy="1.5708 -0 0" />
      <geometry>
        <mesh filename="assets/kd_d_302l_6061.stl" />
      </geometry>
    </collision>
    
    <visual>
      <origin xyz="-0.03745 -0.021 -0.212" rpy="0.628319 0 3.14159" />
      <geometry>
        <mesh filename="assets/ball_bearing_37x25x7.stl" />
      </geometry>
      <material name="ball_bearing_37x25x7_4_material">
        <color rgba="0.717647 0.709804 0.701961 1" />
      </material>
    </visual>
    <collision>
      <origin xyz="-0.03745 -0.021 -0.212" rpy="0.628319 0 3.14159" />
      <geometry>
        <mesh filename="assets/ball_bearing_37x25x7.stl" />
      </geometry>
    </collision>
    
    <visual>
      <origin xyz="0.126 -0.004 -0.66" rpy="1.5708 -0 0" />
      <geometry>
        <mesh filename="assets/rs04.stl" />
      </geometry>
      <material name="rs04_4_material">
        <color rgba="0.929412 0.505882 0 1" />
      </material>
    </visual>
    <collision>
      <origin xyz="0.126 -0.004 -0.66" rpy="1.5708 -0 0" />
      <geometry>
        <mesh filename="assets/rs04.stl" />
      </geometry>
    </collision>
    
    <visual>
      <origin xyz="0.126 -0.004 0.236" rpy="1.5708 -0 0" />
      <geometry>
        <mesh filename="assets/kd_d_301l_6061.stl" />
      </geometry>
      <material name="kd_d_301l_6061_material">
        <color rgba="0.956863 0.956863 0.964706 1" />
      </material>
    </visual>
    <collision>
      <origin xyz="0.126 -0.004 0.236" rpy="1.5708 -0 0" />
      <geometry>
        <mesh filename="assets/kd_d_301l_6061.stl" />
      </geometry>
    </collision>
    
    <visual>
      <origin xyz="0.126 0.331447 -0.489081" rpy="0.628319 0 3.14159" />
      <geometry>
        <mesh filename="assets/kd_d_403_6061.stl" />
      </geometry>
      <material name="kd_d_403_6061_2_material">
        <color rgba="0.956863 0.956863 0.964706 1" />
      </material>
    </visual>
    <collision>
      <origin xyz="0.126 0.331447 -0.489081" rpy="0.628319 0 3.14159" />
      <geometry>
        <mesh filename="assets/kd_d_403_6061.stl" />
      </geometry>
    </collision>
  </link>
  
  <link name="kd_d_401l_6061">
    <inertial>
      <origin xyz="-0.123967 0.0317008 0.0185003" rpy="0 0 0" />
      <mass value="2.09831" />
      <inertia ixx="0.00343085" ixy="0.000744958" ixz="0.000683521" iyy="0.0173864" iyz="-4.0942e-05" izz="0.0172971" />
    </inertial>
    
    <visual>
      <origin xyz="-0.102553 0.176632 -0.533" rpy="1.5708 -0 1.5708" />
      <geometry>
        <mesh filename="assets/rs02.stl" />
      </geometry>
      <material name="rs02_3_material">
        <color rgba="0.929412 0.505882 0 1" />
      </material>
    </visual>
    <collision>
      <origin xyz="-0.102553 0.176632 -0.533" rpy="1.5708 -0 1.5708" />
      <geometry>
        <mesh filename="assets/rs02.stl" />
      </geometry>
    </collision>
    
    <visual>
      <origin xyz="0.448 0.017 -0.106" rpy="1.5708 -1.5708 0" />
      <geometry>
        <mesh filename="assets/kd_d_402l_6061.stl" />
      </geometry>
      <material name="kd_d_402l_6061_material">
        <color rgba="0.882353 0.882353 0.882353 1" />
      </material>
    </visual>
    <collision>
      <origin xyz="0.448 0.017 -0.106" rpy="1.5708 -1.5708 0" />
      <geometry>
        <mesh filename="assets/kd_d_402l_6061.stl" />
      </geometry>
    </collision>
    
    <visual>
      <origin xyz="0.448 0.017 -0.106" rpy="1.5708 1.5708 0" />
      <geometry>
        <mesh filename="assets/kd_d_401l_6061.stl" />
      </geometry>
      <material name="kd_d_401l_6061_material">
        <color rgba="0.956863 0.956863 0.964706 1" />
      </material>
    </visual>
    <collision>
      <origin xyz="0.448 0.017 -0.106" rpy="1.5708 1.5708 0" />
      <geometry>
        <mesh filename="assets/kd_d_401l_6061.stl" />
      </geometry>
    </collision>
    
    <visual>
      <origin xyz="-0.194052 0.062872 0.02" rpy="0 -1.5708 0" />
      <geometry>
        <mesh filename="assets/l_end_stop_ankle_6061.stl" />
      </geometry>
      <material name="l_end_stop_ankle_6061_material">
        <color rgba="0.956863 0.956863 0.964706 1" />
      </material>
    </visual>
    <collision>
      <origin xyz="-0.194052 0.062872 0.02" rpy="0 -1.5708 0" />
      <geometry>
        <mesh filename="assets/l_end_stop_ankle_6061.stl" />
      </geometry>
    </collision>
    
    <visual>
      <origin xyz="-0.658552 0.176632 0.017" rpy="-3.14159 -0 1.5708" />
      <geometry>
        <mesh filename="assets/kd_d_502_6061.stl" />
      </geometry>
      <material name="kd_d_502_6061_3_material">
        <color rgba="0.956863 0.956863 0.964706 1" />
      </material>
    </visual>
    <collision>
      <origin xyz="-0.658552 0.176632 0.017" rpy="-3.14159 -0 1.5708" />
      <geometry>
        <mesh filename="assets/kd_d_502_6061.stl" />
      </geometry>
    </collision>
    
    <visual>
      <origin xyz="-0.191052 0.176632 -0.533" rpy="1.5708 -0 1.5708" />
      <geometry>
        <mesh filename="assets/rs02.stl" />
      </geometry>
      <material name="rs02_4_material">
        <color rgba="0.929412 0.505882 0 1" />
      </material>
    </visual>
    <collision>
      <origin xyz="-0.191052 0.176632 -0.533" rpy="1.5708 -0 1.5708" />
      <geometry>
        <mesh filename="assets/rs02.stl" />
      </geometry>
    </collision>
    
    <visual>
      <origin xyz="0.358947 0.176632 0.023" rpy="0 -0 1.5708" />
      <geometry>
        <mesh filename="assets/kd_d_502_6061.stl" />
      </geometry>
      <material name="kd_d_502_6061_4_material">
        <color rgba="0.956863 0.956863 0.964706 1" />
      </material>
    </visual>
    <collision>
      <origin xyz="0.358947 0.176632 0.023" rpy="0 -0 1.5708" />
      <geometry>
        <mesh filename="assets/kd_d_502_6061.stl" />
      </geometry>
    </collision>
    
    <visual>
      <origin xyz="-0.105552 0.062872 0.02" rpy="-0 1.5708 0" />
      <geometry>
        <mesh filename="assets/l_end_stop_ankle_6061.stl" />
      </geometry>
      <material name="l_end_stop_ankle_6061_2_material">
        <color rgba="0.956863 0.956863 0.964706 1" />
      </material>
    </visual>
    <collision>
      <origin xyz="-0.105552 0.062872 0.02" rpy="-0 1.5708 0" />
      <geometry>
        <mesh filename="assets/l_end_stop_ankle_6061.stl" />
      </geometry>
    </collision>
  </link>
  
  <link name="arb_uj111_cross_bearing_2">
    <inertial>
      <origin xyz="8.901e-09 -1.5576e-08 -0.03" rpy="0 0 0" />
      <mass value="0.110039" />
      <inertia ixx="4.55522e-05" ixy="1.4e-11" ixz="1e-12" iyy="2.63882e-05" iyz="-4e-12" izz="2.63882e-05" />
    </inertial>
    
    <visual>
      <origin xyz="0 -0 -0.03" rpy="-1.5708 -1.5708 0" />
      <geometry>
        <mesh filename="assets/arb_uj111_cross_bearing.stl" />
      </geometry>
      <material name="arb_uj111_cross_bearing_2_material">
        <color rgba="0.72549 0.733333 0.717647 1" />
      </material>
    </visual>
    <collision>
      <origin xyz="0 -0 -0.03" rpy="-1.5708 -1.5708 0" />
      <geometry>
        <mesh filename="assets/arb_uj111_cross_bearing.stl" />
      </geometry>
    </collision>
  </link>
  
  <link name="foot_6061_2">
    <inertial>
      <origin xyz="-9.04e-10 0.0327815 -0.069626" rpy="0 0 0" />
      <mass value="0.427779" />
      <inertia ixx="0.0014449" ixy="-9e-12" ixz="-0" iyy="0.00161841" iyz="5.78063e-05" izz="0.00028165" />
    </inertial>
    
    <visual>
      <origin xyz="-0.0425 0.043 0.02" rpy="1.5708 1.5708 0" />
      <geometry>
        <mesh filename="assets/foot_6061.stl" />
      </geometry>
      <material name="foot_6061_2_material">
        <color rgba="0.956863 0.956863 0.964706 1" />
      </material>
    </visual>
    <collision>
      <origin xyz="-0.0425 0.043 0.02" rpy="1.5708 1.5708 0" />
      <geometry>
        <mesh filename="assets/foot_6061.stl" />
      </geometry>
    </collision>
  </link>
  
  <joint name="left_foot_roll_02" type="revolute">
    <origin xyz="0 0.03 -0.03" rpy="-1.5708 -1.5708 0" />
    <parent link="arb_uj111_cross_bearing_2" />
    <child link="foot_6061_2" />
    <axis xyz="0 0 1" />
    <limit effort="15" velocity="10" lower="-0.261799" upper="0.261799" />
  </joint>
  
  <joint name="left_foot_pitch_02" type="revolute">
    <origin xyz="-0.288552 0.0325676 0.05" rpy="-0 -0 -3.14159" />
    <parent link="kd_d_401l_6061" />
    <child link="arb_uj111_cross_bearing_2" />
    <axis xyz="0 0 1" />
    <limit effort="15" velocity="10" lower="-0.872665" upper="0.523599" />
  </joint>
  
  <joint name="left_knee_04" type="revolute">
    <origin xyz="0.02 -0.021 -0.212" rpy="-0 -1.5708 0" />
    <parent link="kd_d_301l_6061" />
    <child link="kd_d_401l_6061" />
    <axis xyz="0 0 1" />
    <limit effort="100" velocity="10" lower="0" upper="2.70526" />
  </joint>
  
  <joint name="left_hip_yaw_03" type="revolute">
    <origin xyz="0 0.142 -0.02525" rpy="1.5708 0 0" />
    <parent link="rs03" />
    <child link="kd_d_301l_6061" />
    <axis xyz="0 0 1" />
    <limit effort="50" velocity="10" lower="-1.5708" upper="1.5708" />
  </joint>
  
  <joint name="left_hip_roll_03" type="revolute">
    <origin xyz="0.02925 -0.03 -0.071" rpy="-3.14159 -1.5708 0" />
    <parent link="kd_d_102l_6061" />
    <child link="rs03" />
    <axis xyz="0 0 1" />
    <limit effort="50" velocity="10" lower="-0.20944" upper="2.26893" />
  </joint>
  
  <joint name="left_hip_pitch_04" type="revolute">
    <origin xyz="0.055 -0.0246054 -0.0595116" rpy="1.5708 0 -1.5708" />
    <parent link="assy_formfg___kd_b_102b_torso_btm" />
    <child link="kd_d_102l_6061" />
    <axis xyz="0 0 1" />
    <limit effort="100" velocity="10" lower="-1.0472" upper="2.21657" />
  </joint>
  
  <link name="battery_chest">
    <inertial>
      <origin xyz="0 0 0" rpy="0 0 0" />
      <mass value="10.0" />
      <inertia ixx="0.0453" ixy="0" ixz="0" iyy="0.0453" iyz="0" izz="0.0240" />
    </inertial>
    <visual>
      <geometry>
        <box size="0.12 0.12 0.20" />
      </geometry>
      <material name="battery_material">
        <color rgba="0.2 0.2 0.2 1" />
      </material>
    </visual>
    <collision>
      <geometry>
        <box size="0.12 0.12 0.20" />
      </geometry>
    </collision>
  </link>
  
  <joint name="torso_to_battery" type="fixed">
    <origin xyz="0 0 0.10" rpy="0 0 0" />
    <parent link="assy_formfg___kd_b_102b_torso_btm" />
    <child link="battery_chest" />
  </joint>
</robot>